
        <mujoco model="bicycle">
            <compiler angle="degree" coordinate="local"/>
            <option timestep="0.01" gravity="0 0 -9.81"/>
            
        <asset>
            <mesh name="wheel_torus" builtin="supertorus" params="64 0.025 1 1" scale="0.35 0.35 0.35"/>
        </asset>
        
            <default>
                <joint limited="true" damping="0.01"/>
                <geom friction="0.8 0.1 0.1" rgba="0.8 0.6 0.4 1"/>
            </default>

            
        <worldbody>
            <body name="bicycle" pos="0 0 0.35">
                <freejoint name="bicycle_free"/>
                <body name="frame" pos="0 0 0">
                    <geom name="seat tube" type="capsule" fromto="0.0 0.0 0.0  -0.076545205528036 0.0 0.5446474378078637" size="0.016"/>
                    <geom name="down tube" type="capsule" fromto="0.0 0.0 0.0  0.46371960525899625 0.0 0.5418011782380016" size="0.016"/>
                    <geom name="top tube" type="capsule" fromto="0.46371960525899625 0.0 0.5418011782380016  -0.076545205528036 0.0 0.5446474378078637" size="0.016"/>
                    <geom name="chain stay left" type="capsule" fromto="-0.02 -0.02 0.0  -0.4 -0.02 0.03" size="0.016"/>
                    <geom name="chain stay right" type="capsule" fromto="-0.02 0.02 0.0  -0.4 0.02 0.03" size="0.016"/>
                    <geom name="seat stay left" type="capsule" fromto="-0.4 -0.02 0.03  -0.076545205528036 0.0 0.5446474378078637" size="0.016"/>
                    <geom name="seat stay right" type="capsule" fromto="-0.4 0.02 0.03  -0.076545205528036 0.0 0.5446474378078637" size="0.016"/>
                    <body name="rear wheel" pos="-0.4 0.0 0.03" euler="90 0 0">
                        <joint name="rear wheel hinge" type="hinge" axis="0 0 -1" pos="0 0 0" limited="false"/>
                        <geom name="rear wheel geom" type="mesh" mesh="wheel_torus" rgba="0.1 0.1 0.1 1" contype="2" conaffinity="2"/>
                    </body>
                </body>
                <body name="front fork" pos="0.65 0.0 0.03" euler="0 -20.0 0">
                    <joint name="steer" type="hinge" axis="0 0 1" pos="0 0 0" range="-35 35"/>
                    <geom name="head tube" type="capsule" fromto="0 0 0.5446474378078637 0 0 0.6446474378078637" size="0.016"/>
                    <geom name="handlebar" type="capsule" fromto="0 -0.15 0.6446474378078637 0 0.15 0.6446474378078637" size="0.016"/>
                    <geom name="fork left" type="capsule" fromto="0 -0.02 0 0 -0.02 0.5446474378078637" size="0.016"/>
                    <geom name="fork right" type="capsule" fromto="0 0.02 0 0 0.02 0.5446474378078637" size="0.016"/>
                    <body name="front wheel" pos="0 0 0" euler="90 0 0">
                        <joint name="front wheel hinge" type="hinge" axis="0 0 -1" pos="0 0 0" limited="false"/>
                        <geom name="front wheel geom" type="mesh" mesh="wheel_torus" rgba="0.1 0.1 0.1 1" contype="2" conaffinity="2"/>
                    </body>
                </body>
            </body>
        </worldbody>
            
        <actuator>
            <motor joint="rear wheel hinge"/>
            <motor joint="steer"/>
        </actuator>
        

            <size njmax="100" nconmax="50"/>
        </mujoco>
        